Traceback (most recent call last):
  File "E:\MainHomePage\.M_HomePage\Lib\site-packages\jupyter_cache\executors\utils.py", line 58, in single_nb_execution
    executenb(
  File "E:\MainHomePage\.M_HomePage\Lib\site-packages\nbclient\client.py", line 1314, in execute
    return NotebookClient(nb=nb, resources=resources, km=km, **kwargs).execute()
           ^^^^^^^^^^^^^^^^^^^^^^^^^^^^^^^^^^^^^^^^^^^^^^^^^^^^^^^^^^^^^^^^^^^^^
  File "E:\MainHomePage\.M_HomePage\Lib\site-packages\jupyter_core\utils\__init__.py", line 165, in wrapped
    return loop.run_until_complete(inner)
           ^^^^^^^^^^^^^^^^^^^^^^^^^^^^^^
  File "C:\Users\Dr\AppData\Local\Programs\Python\Python312\Lib\asyncio\base_events.py", line 687, in run_until_complete
    return future.result()
           ^^^^^^^^^^^^^^^
  File "E:\MainHomePage\.M_HomePage\Lib\site-packages\nbclient\client.py", line 709, in async_execute
    await self.async_execute_cell(
  File "E:\MainHomePage\.M_HomePage\Lib\site-packages\nbclient\client.py", line 1062, in async_execute_cell
    await self._check_raise_for_error(cell, cell_index, exec_reply)
  File "E:\MainHomePage\.M_HomePage\Lib\site-packages\nbclient\client.py", line 918, in _check_raise_for_error
    raise CellExecutionError.from_cell_and_msg(cell, exec_reply_content)
nbclient.exceptions.CellExecutionError: An error occurred while executing the following cell:
------------------
import numpy as np
import matplotlib.pyplot as plt
import pandas as pd

dataset = pd.read_csv('./assets/Corona_NLP_train.csv', encoding='latin1')
import re 
texts=[]
for i in range(0,len(dataset)):
  text = re.sub('[^a-zA-Z]' , ' ', dataset['OriginalTweet'][i])
  text = text.lower()
  text = text.split()
  x = len(text) if text.count('https') ==0  else text.index('https') 
  text = text[: x ]
  text = [t for t in text if not t=='https']
  text = ' '.join(text)
  texts.append(text)

from gensim.models import Word2Vec
sentences = [line.split() for line in texts]

w2v =Word2Vec(sentences, vector_size=100, window=5, workers=4, epochs=10, min_count=5)
print(sentences[20:25]) #Training the word2vec model
------------------


[1;31m---------------------------------------------------------------------------[0m
[1;31mModuleNotFoundError[0m                       Traceback (most recent call last)
Cell [1;32mIn[1], line 18[0m
[0;32m     15[0m   text [38;5;241m=[39m [38;5;124m'[39m[38;5;124m [39m[38;5;124m'[39m[38;5;241m.[39mjoin(text)
[0;32m     16[0m   texts[38;5;241m.[39mappend(text)
[1;32m---> 18[0m [38;5;28;01mfrom[39;00m [38;5;21;01mgensim[39;00m[38;5;21;01m.[39;00m[38;5;21;01mmodels[39;00m [38;5;28;01mimport[39;00m Word2Vec
[0;32m     19[0m sentences [38;5;241m=[39m [line[38;5;241m.[39msplit() [38;5;28;01mfor[39;00m line [38;5;129;01min[39;00m texts]
[0;32m     21[0m w2v [38;5;241m=[39mWord2Vec(sentences, vector_size[38;5;241m=[39m[38;5;241m100[39m, window[38;5;241m=[39m[38;5;241m5[39m, workers[38;5;241m=[39m[38;5;241m4[39m, epochs[38;5;241m=[39m[38;5;241m10[39m, min_count[38;5;241m=[39m[38;5;241m5[39m)

[1;31mModuleNotFoundError[0m: No module named 'gensim'

